<!DOCTYPE html>
<html>
<head>
  <meta charset="utf-8">
  <meta name="generator" content="pandoc">
  <meta name="viewport" content="width=device-width, initial-scale=1.0, user-scalable=yes">
  <link rel="icon" href="../favicon.ico" />
  <link rel="stylesheet" href="../style.css">
  <title>Ruby - レスキュー後に特定の例外を確認する方法は? | Techioz</title>
  <style type="text/css">code{white-space: pre;}</style>
  <script async src="https://pagead2.googlesyndication.com/pagead/js/adsbygoogle.js?client=ca-pub-1637770322917058"
     crossorigin="anonymous"></script>
  <!-- Google tag (gtag.js) -->
  <script async src="https://www.googletagmanager.com/gtag/js?id=G-DRM1ZRNLDN"></script>
  <script>
    window.dataLayer = window.dataLayer || [];
    function gtag(){dataLayer.push(arguments);}
    gtag('js', new Date());

    gtag('config', 'G-DRM1ZRNLDN');
  </script>
<script type="application/ld+json">
{
  "@context": "http://schema.org",
  "@type": "Article",
  "headline": "Ruby - レスキュー後に特定の例外を確認する方法は?",
  "author": {
    "@type": "Person",
    "address": "",
    "email": null,
    "identifier": "masyumaroking",
    "name": "masyumaroking"
  },
  "publisher": {
    "@type": "Person",
    "name": "masyumaroking"
  }
}
</script>
  <!--[if lt IE 9]>
    <script src="//cdnjs.cloudflare.com/ajax/libs/html5shiv/3.7.3/html5shiv-printshiv.min.js"></script>
  <![endif]-->
</head>
<body>
  <header>
    <div class="container">
        <h1>Techioz Blog</h1>
        <nav>
            <ul>
                <li><a href="#">Home</a></li>
                <li><a href="#">Articles</a></li>
                <li><a href="#">About</a></li>
                <li><a href="#">Contact</a></li>
            </ul>
        </nav>
    </div>
  </header>
  <main>
    <div class="container">
        <article>
                      <h2>Ruby -
レスキュー後に特定の例外を確認する方法は?</h2>
                    <h2 id="概要">概要</h2>
                    <p>Ruby
                    では、特定の例外に対して何か特別なことをしたいのですが、特定の救済を行うには十分ではありません。レスキュー内の特定の例外をチェックするための適切な構文は何ですか?</p>
                    <p>サンプル (動作しない) コード:</p>
                    <pre><code>begin
   c = d
rescue =&gt; ex
  if ex == NameError
    puts &#39;NameError&#39;
  else
    puts ex.message
  end
end
</code></pre>
                    <h2 id="解決策">解決策</h2>
                    <p>あなたの例では、 ex
                    は例外のインスタンスであり、Class オブジェクトである
                    ==
                    演算子を使用してクラス自体と比較すると、期待される結果が得られません。エラーのクラスを実際のクラス
                    オブジェクトと比較して確認する必要があります。</p>
                    <pre><code># A NameError or an error that is a subclass of NameError
ex.is_a?(NameError)
ex.kind_of?(NameError)

# NameError ONLY, not even sub-classes of NameError
ex.instance_of?(NameError)
</code></pre>
                    <p>他にも確認できる方法は多数ありますが、私が概説した以前の方法が最も一般的に使用され、通常は「推奨される」方法です。クラスに対して等価性を使用することもできますが、これは柔軟性が低く、根本的な意図が明確ではないため、通常はこれを実現する推奨方法ではありません。上記の例は、クラスのサブクラスをどのように処理するかを正確に示しています。指定されたエラー。</p>
                    <pre><code>ex.class == NameError
</code></pre>
                    <p>微妙な違いをうまく説明しているこの回答を見つけました。</p>
        </article>
    </div>
  </main>
  <footer>
    <div class="container">
        <p>&copy; 2024 Techioz. All rights reserved.</p>
    </div>
  </footer>
</body>
</html>